Initialized project.
Using environment configuration: StandardEnvironment
/var/lib/condor/execute/slot1/dir_939075/analyze.py:15: RuntimeWarning: divide by zero encountered in divide
  return -1*(job.sp.A/6)*((2*job.sp.r*job.sp.r)/(r**2-(job.sp.r+job.sp.r)**2)+(2*job.sp.r*job.sp.r)/(r**2-(job.sp.r-job.sp.r)**2)+np.log((r**2-(job.sp.r+job.sp.r)**2)/(r**2-(job.sp.r-job.sp.r)**2)))
/var/lib/condor/execute/slot1/dir_939075/analyze.py:15: RuntimeWarning: invalid value encountered in log
  return -1*(job.sp.A/6)*((2*job.sp.r*job.sp.r)/(r**2-(job.sp.r+job.sp.r)**2)+(2*job.sp.r*job.sp.r)/(r**2-(job.sp.r-job.sp.r)**2)+np.log((r**2-(job.sp.r+job.sp.r)**2)/(r**2-(job.sp.r-job.sp.r)**2)))
Traceback (most recent call last):
  File "/var/lib/condor/execute/slot1/dir_939075/miniforge3/envs/lammps/lib/python3.11/site-packages/flow/project.py", line 3475, in _execute_operation
    self._operations[operation.name](*operation._jobs)
  File "/var/lib/condor/execute/slot1/dir_939075/miniforge3/envs/lammps/lib/python3.11/site-packages/flow/project.py", line 625, in __call__
    return self._op_func(*jobs)
           ^^^^^^^^^^^^^^^^^^^^
  File "/var/lib/condor/execute/slot1/dir_939075/project.py", line 40, in run_mc
    shutil.copy("input.run.lammps", job.fn("input.run.lammps"))
  File "/var/lib/condor/execute/slot1/dir_939075/miniforge3/envs/lammps/lib/python3.11/shutil.py", line 431, in copy
    copyfile(src, dst, follow_symlinks=follow_symlinks)
  File "/var/lib/condor/execute/slot1/dir_939075/miniforge3/envs/lammps/lib/python3.11/shutil.py", line 256, in copyfile
    with open(src, 'rb') as fsrc:
         ^^^^^^^^^^^^^^^
FileNotFoundError: [Errno 2] No such file or directory: 'input.run.lammps'

The above exception was the direct cause of the following exception:

Traceback (most recent call last):
  File "/var/lib/condor/execute/slot1/dir_939075/project.py", line 70, in <module>
    MyProject().main()
  File "/var/lib/condor/execute/slot1/dir_939075/miniforge3/envs/lammps/lib/python3.11/site-packages/flow/project.py", line 5132, in main
    args.func(args)
  File "/var/lib/condor/execute/slot1/dir_939075/miniforge3/envs/lammps/lib/python3.11/site-packages/flow/project.py", line 4844, in _main_run
    run()
  File "/var/lib/condor/execute/slot1/dir_939075/miniforge3/envs/lammps/lib/python3.11/site-packages/flow/project.py", line 3720, in run
    self._run_operations(
  File "/var/lib/condor/execute/slot1/dir_939075/miniforge3/envs/lammps/lib/python3.11/site-packages/flow/project.py", line 3305, in _run_operations
    self._execute_operation(operation, timeout, pretend)
  File "/var/lib/condor/execute/slot1/dir_939075/miniforge3/envs/lammps/lib/python3.11/site-packages/flow/project.py", line 3477, in _execute_operation
    raise UserOperationError(execution_error_message) from error
flow.errors.UserOperationError: An exception was raised during operation run_mc for job or aggregate with id 50d3e72246fe9dfa72aa32022c9e69fe.
